<?xml version="1.0"?>
<robot xmlns:xacro="http://www.ros.org/wiki/xacro" >

  <xacro:include filename="inertial_macros.xacro"/>



  <material name="white">
    <color rgba="1 1 1 1" />
  </material>

  <material name="orange">
    <color rgba="1 0.2 0.1 1" />
  </material>
 
  <material name="blue">
    <color rgba="0.2 0.2 1 1" /> 
  </material>

  <material name="black">
   <color rgba="0 0 0 1" />
  </material>
  
  
  

  <link name="base_link">
  </link>

  <joint name="chassis_joint" type="fixed">
    <parent link="base_link"/>
    <child link="chassis"/>
    <origin xyz="0 0 -0.007"/>
  </joint>
  
  <link name="chassis">
    <visual>
      <origin xyz="0 0 0"/>
      <geometry>
        <box size="0.40 0.40 0.004"/>
      </geometry>
      <material name="white"/>
    </visual>
    <collision>
      <origin xyz="0 0 0"/>
      <geometry>
        <box size="0.42 0.42 0.0045"/>
      </geometry>
    </collision>
    <xacro:inertial_box mass="0.5" x="0.4" y="0.4" z="0.004" >
      <origin xyz="0 0 0" rpy="0 0 0"/>
    </xacro:inertial_box>   
  </link>  




  <joint name="right_front_wheel_joint" type="continuous">
    <parent link="base_link"/>
    <child link="right_front_wheel"/>
    <origin xyz="0.14 -0.14 0" rpy="-${pi/2} 0 0"/>
    <axis xyz="0 0 0.1"/>
  </joint>
  
  <link name="right_front_wheel">
    <visual>
      <origin xyz="0 0 0"/>
      <geometry>
        <cylinder radius="0.04" length="0.04"/>
      </geometry>
      <material name="blue"/>
    </visual>
    <collision>
      <origin xyz="0 0 0"/>
      <geometry>
        <cylinder radius="0.044" length="0.044"/>
      </geometry>
    </collision>
    <xacro:inertial_cylinder mass="0.1" length="0.4" radius="0.4">
      <origin xyz="0 0 0" rpy="0 0 0"/>
    </xacro:inertial_cylinder>
  </link>    

  <joint name="left_front_wheel_joint" type="continuous">
    <parent link="base_link"/>
    <child link="left_front_wheel"/>
    <origin xyz="0.14 0.14 0" rpy="${pi/2} 0 0"/>
    <axis xyz="0 0 0.1"/>
  </joint>
  
  <link name="left_front_wheel">
    <visual>
      <origin xyz="0 0 0"/>
      <geometry>
        <cylinder radius="0.04" length="0.04"/>
      </geometry>
      <material name="blue"/>
    </visual>
    <collision>
      <origin xyz="0 0 0"/>
      <geometry>
        <cylinder radius="0.044" length="0.044"/>
      </geometry>
    </collision>
    <xacro:inertial_cylinder mass="0.1" length="0.4" radius="0.4">
      <origin xyz="0 0 0" rpy="0 0 0"/>
    </xacro:inertial_cylinder>
  </link>
  
    <joint name="right_back_wheel_joint" type="continuous">
    <parent link="base_link"/>
    <child link="right_back_wheel"/>
    <origin xyz="-0.14 -0.14 0" rpy="-${pi/2} 0 0"/>
    <axis xyz="0 0 0.1"/>
  </joint>
  
  <link name="right_back_wheel">
    <visual>
      <origin xyz="0 0 0"/>
      <geometry>
        <cylinder radius="0.04" length="0.04"/>
      </geometry>
      <material name="blue"/>
    </visual>
    <collision>
      <origin xyz="0 0 0"/>
      <geometry>
        <cylinder radius="0.044" length="0.044"/>
      </geometry>
    </collision>
    <xacro:inertial_cylinder mass="0.1" length="0.4" radius="0.4">
      <origin xyz="0 0 0" rpy="0 0 0"/>
    </xacro:inertial_cylinder>
  </link>    

  <joint name="left_back_wheel_joint" type="continuous">
    <parent link="base_link"/>
    <child link="left_back_wheel"/>
    <origin xyz="-0.14 0.14 0" rpy="${pi/2} 0 0"/>
    <axis xyz="0 0 0.1"/>
  </joint>
  
  <link name="left_back_wheel">
    <visual>
      <origin xyz="0 0 0"/>
      <geometry>
        <cylinder radius="0.04" length="0.04"/>
      </geometry>
      <material name="blue"/>
    </visual>
    <collision>
      <origin xyz="0 0 0"/>
      <geometry>
        <cylinder radius="0.044" length="0.044"/>
      </geometry>
    </collision>
    <xacro:inertial_cylinder mass="0.1" length="0.4" radius="0.4">
      <origin xyz="0 0 0" rpy="0 0 0"/>
    </xacro:inertial_cylinder>
  </link>
      
</robot>

